Workbook

Sheet Dataset
A1: City | B1: Month | C1: Product_Category | D1: Units_Sold | E1: Unit_Price | F1: Total_Sales | G1: Customer_Count
A2: Hyderabad | B2: Apr | C2: Smartphones | D2: 870 | E2: 5429.54 | F2: 4723698 | G2: 642
A3: Bangalore | B3: Jul | C3: Tablets | D3: 287 | E3: 7156.91 | F3: 2054033 | G3: 224
A4: Ahmedabad | B4: Aug | C4: Tablets | D4: 349 | E4: 6723.95 | F4: 2346658 | G4: 326
A5: Delhi | B5: Dec | C5: Smartphones | D5: 760 | E5: 5268.1 | F5: 4003753 | G5: 589
A6: Kolkata | B6: Dec | C6: Smartphones | D6: 1160 | E6: 4812.18 | F6: 5582127 | G6: 825
A7: Bangalore | B7: Dec | C7: Tablets | D7: 443 | E7: 6881.03 | F7: 3048297 | G7: 375
A8: Bangalore | B8: May | C8: Tablets | D8: 334 | E8: 6519.92 | F8: 2177655 | G8: 241
A9: Chennai | B9: Dec | C9: Tablets | D9: 463 | E9: 6984.23 | F9: 3233699 | G9: 328
A10: Mumbai | B10: Apr | C10: Laptops | D10: 203 | E10: 21142.61 | F10: 4291949 | G10: 152
A11: Chennai | B11: Jun | C11: Smartphones | D11: 1001 | E11: 5604.85 | F11: 5610453 | G11: 894
A12: Delhi | B12: Oct | C12: Laptops | D12: 113 | E12: 20774.25 | F12: 2347490 | G12: 95
A13: Surat | B13: Aug | C13: Smartphones | D13: 937 | E13: 5537.73 | F13: 5188848 | G13: 782
... A201: Ahmedabad | B201: Sep | C201: Laptops | D201: 188 | E201: 22244.2 | F201: 4181910 | G201: 161

Sheet Aggregated Dataset
A1: City | B1: Month | C1: Product_Category | D1: Units_Sold | E1: Unit_Price | F1: Total_Sales | G1: Customer_Count | H1: Variable_Cost_Per_Unit | I1: Contribution_Margin
A2: Hyderabad | B2: Apr | C2: Smartphones | D2: 870 | E2: 5429.54 | F2: 4723698 | G2: 642 | H2: =$E2*0.6 -> 3257.724 | I2: =($E2-$H2)*$D2 -> 1889479.9
A3: Bangalore | B3: Jul | C3: Tablets | D3: 287 | E3: 7156.91 | F3: 2054033 | G3: 224 | H3: =$E3*0.6 -> 4294.146 | I3: =($E3-$H3)*$D3 -> 821613.27
A4: Ahmedabad | B4: Aug | C4: Tablets | D4: 349 | E4: 6723.95 | F4: 2346658 | G4: 326 | H4: =$E4*0.6 -> 4034.37 | I4: =($E4-$H4)*$D4 -> 938663.42
A5: Delhi | B5: Dec | C5: Smartphones | D5: 760 | E5: 5268.1 | F5: 4003753 | G5: 589 | H5: =$E5*0.6 -> 3160.86 | I5: =($E5-$H5)*$D5 -> 1601502.4
A6: Kolkata | B6: Dec | C6: Smartphones | D6: 1160 | E6: 4812.18 | F6: 5582127 | G6: 825 | H6: =$E6*0.6 -> 2887.308 | I6: =($E6-$H6)*$D6 -> 2232851.5
A7: Bangalore | B7: Dec | C7: Tablets | D7: 443 | E7: 6881.03 | F7: 3048297 | G7: 375 | H7: =$E7*0.6 -> 4128.618 | I7: =($E7-$H7)*$D7 -> 1219318.5
A8: Bangalore | B8: May | C8: Tablets | D8: 334 | E8: 6519.92 | F8: 2177655 | G8: 241 | H8: =$E8*0.6 -> 3911.952 | I8: =($E8-$H8)*$D8 -> 871061.31
A9: Chennai | B9: Dec | C9: Tablets | D9: 463 | E9: 6984.23 | F9: 3233699 | G9: 328 | H9: =$E9*0.6 -> 4190.538 | I9: =($E9-$H9)*$D9 -> 1293479.4
A10: Mumbai | B10: Apr | C10: Laptops | D10: 203 | E10: 21142.61 | F10: 4291949 | G10: 152 | H10: =$E10*0.6 -> 12685.566 | I10: =($E10-$H10)*$D10 -> 1716779.9
A11: Chennai | B11: Jun | C11: Smartphones | D11: 1001 | E11: 5604.85 | F11: 5610453 | G11: 894 | H11: =$E11*0.6 -> 3362.91 | I11: =($E11-$H11)*$D11 -> 2244181.9
A12: Delhi | B12: Oct | C12: Laptops | D12: 113 | E12: 20774.25 | F12: 2347490 | G12: 95 | H12: =$E12*0.6 -> 12464.55 | I12: =($E12-$H12)*$D12 -> 938996.1
A13: Surat | B13: Aug | C13: Smartphones | D13: 937 | E13: 5537.73 | F13: 5188848 | G13: 782 | H13: =$E13*0.6 -> 3322.638 | I13: =($E13-$H13)*$D13 -> 2075541.2
... A201: Ahmedabad | B201: Sep | C201: Laptops | D201: 188 | E201: 22244.2 | F201: 4181910 | G201: 161 | H201: =$E201*0.6 -> 13346.52 | I201: =($E201-$H201)*$D201 -> 1672763.8

Sheet Solutions
B1: PART A
B3: Assumption: We assume that the Variable Cost for all products is 60% of the original Unit Price across all categories and cities. This implies a standard Gross Margin of 40%
B5: Month | C5: Revenues | D5: Contribution Margin
B6: Jan | C6: =GETPIVOTDATA("Total_Sales",'Pivot Table 1'!B4,"Monthly Trend", $B6) -> 41857858 | D6: =GETPIVOTDATA("Contribution_Margin",'Pivot Table 1'!C2,"Monthly Trend",$B6) -> 16743143
B7: Feb | C7: =GETPIVOTDATA("Total_Sales",'Pivot Table 1'!B5,"Monthly Trend", $B7) -> 55905036 | D7: =GETPIVOTDATA("Contribution_Margin",'Pivot Table 1'!C3,"Monthly Trend",$B7) -> 22362015
B8: Mar | C8: =GETPIVOTDATA("Total_Sales",'Pivot Table 1'!B6,"Monthly Trend", $B8) -> 45259129 | D8: =GETPIVOTDATA("Contribution_Margin",'Pivot Table 1'!C4,"Monthly Trend",$B8) -> 18103652
B9: Apr | C9: =GETPIVOTDATA("Total_Sales",'Pivot Table 1'!B7,"Monthly Trend", $B9) -> 63959180 | D9: =GETPIVOTDATA("Contribution_Margin",'Pivot Table 1'!C5,"Monthly Trend",$B9) -> 25583672
B10: May | C10: =GETPIVOTDATA("Total_Sales",'Pivot Table 1'!B2,"Monthly Trend", $B10) -> 57749181 | D10: =GETPIVOTDATA("Contribution_Margin",'Pivot Table 1'!C6,"Monthly Trend",$B10) -> 23099674
B11: Jun | C11: =GETPIVOTDATA("Total_Sales",'Pivot Table 1'!B8,"Monthly Trend", $B11) -> 68413072 | D11: =GETPIVOTDATA("Contribution_Margin",'Pivot Table 1'!C7,"Monthly Trend",$B11) -> 27365232
B12: Jul | C12: =GETPIVOTDATA("Total_Sales",'Pivot Table 1'!B9,"Monthly Trend", $B12) -> 49702035 | D12: =GETPIVOTDATA("Contribution_Margin",'Pivot Table 1'!C8,"Monthly Trend",$B12) -> 19880812
B13: Aug | C13: =GETPIVOTDATA("Total_Sales",'Pivot Table 1'!B3,"Monthly Trend", $B13) -> 53305738 | D13: =GETPIVOTDATA("Contribution_Margin",'Pivot Table 1'!C9,"Monthly Trend",$B13) -> 21322296
B14: Sep | C14: =GETPIVOTDATA("Total_Sales",'Pivot Table 1'!B10,"Monthly Trend", $B14) -> 38545556 | D14: =GETPIVOTDATA("Contribution_Margin",'Pivot Table 1'!C10,"Monthly Trend",$B14) -> 15418219
B15: Oct | C15: =GETPIVOTDATA("Total_Sales",'Pivot Table 1'!B11,"Monthly Trend", $B15) -> 53716083 | D15: =GETPIVOTDATA("Contribution_Margin",'Pivot Table 1'!C11,"Monthly Trend",$B15) -> 21486435
B16: Nov | C16: =GETPIVOTDATA("Total_Sales",'Pivot Table 1'!B12,"Monthly Trend", $B16) -> 48388670 | D16: =GETPIVOTDATA("Contribution_Margin",'Pivot Table 1'!C12,"Monthly Trend",$B16) -> 19355469
B17: Dec | C17: =GETPIVOTDATA("Total_Sales",'Pivot Table 1'!B13,"Monthly Trend", $B17) -> 59263858 | D17: =GETPIVOTDATA("Contribution_Margin",'Pivot Table 1'!C13,"Monthly Trend",$B17) -> 23705543
B19: Product | C19: Average Price per Product | D19: Avg Units Sold per Customer
B20: Accessories | C20: ='Pivot Table 1'!B32/'Pivot Table 1'!C32 -> 1214.227 | D20: ='Pivot Table 1'!$C32/'Pivot Table 1'!$D32 -> 1.2140132
B21: Laptops | C21: ='Pivot Table 1'!B33/'Pivot Table 1'!C33 -> 21312.884 | D21: ='Pivot Table 1'!$C33/'Pivot Table 1'!$D33 -> 1.2104694
B22: Smartphones | C22: ='Pivot Table 1'!B34/'Pivot Table 1'!C34 -> 5304.8903 | D22: ='Pivot Table 1'!$C34/'Pivot Table 1'!$D34 -> 1.2135239
B23: Tablets | C23: ='Pivot Table 1'!B35/'Pivot Table 1'!C35 -> 6757.8514 | D23: ='Pivot Table 1'!$C35/'Pivot Table 1'!$D35 -> 1.2110865
B26: PART B
B28: For What If Analysis:
B29: Scenario | C29: Volume Uplift (Change in Units Sold) | E29: Metric | F29: Original Totals | G29: Best-Case | H29: Expected-Case | I29: Worst-Case
B30: Best-Case | C30: Increase in 25% (Multiplier: 1.25) | E30: Total Sales Revenue | F30: =SUM('Aggregated Dataset'!F2:F201) -> 636065396 | G30: =SUM('What If-Best Case Scenario'!L2:L201) -> 6.4684842e+08 | H30: =SUM('What If- Expected Case Scenario'!L2:L201) -> 6.3520276e+08 | I30: =SUM('What If- Worst Case Scenario'!L2:L201) -> 6.2743899e+08
B31: Expected-Case | C31: Increase in 10% (Multiplier: 1.10) | E31: Total Cont. Margin | F31: =SUM('Aggregated Dataset'!I2:I201) -> 2.5442616e+08 | G31: =SUM('What If-Best Case Scenario'!M2:M201) -> 2.5226956e+08 | H31: =SUM('What If- Expected Case Scenario'!M2:M201) -> 2.4838767e+08 | I31: =SUM('What If- Worst Case Scenario'!M2:M201) -> 2.4579975e+08
B32: Worst-Case | C32: 0% (Multiplier: 1.00)
B34: Impact Measure | C34: Best-Case Impact | E34: Impact Measure | F34: Expected-Case Impact | H34: Impact Measure | I34: Worst-Case Impact
B35: Change in Sales Revenue | C35: =G30-F30 -> 10783025 | E35: Change in Sales Revenue | F35: =H30-F30 -> -862631.25 | H35: Change in Sales Revenue | I35: =I30-F30 -> -8626401.9
B36: Change in Cont. Margin | C36: =G31-F31 -> -2156603 | E36: Change in Cont. Margin | F36: =H31-F31 -> -6038488.3 | H36: Change in Cont. Margin | I36: =I31-F31 -> -8626411.8
B39: Scenario | C39: Volume Assumption | D39: Change in Sales Revenue | E39: Change in Cont. Margin
B40: Best Case | C40: (+25%) | D40: 10783025 | E40: -2156603
B41: Expected Case | C41: (+10%) | D41: -862631.25 | E41: -6038488.3
B42: Worst Case | C42: 0 | D42: -8626401.9 | E42: -8626411.8
B44: Interpretation and Conclusion: 1. Financial Failure: Based on my calculations, the 10% discount campaign is financially unsuccessful under all three volume scenarios. 2. Best-Case Profit Loss: Even with the most optimistic 25% volume increase, the campaign generates higher revenue (a gain of Rs. 1.08Cr) but still results in a Rs. 21.57L loss in Contribution Margin (profit). This occurs because the price cut (0.90) is too deep relative to the assumed 60% variable cost, meaning the price cut destroys the margin faster than the volume can recover it. 3.Worst-Case Risk: The maximum downside is a loss of Rs. 86.26L in CM, highlighting the significant financial risk if the promotional volume is flat.
B55: PART C
B57: Scenario | C57: Change in Volume (Units Sold) | D57: Change in Price (Unit Price) | E57: Change in Cost (Variable Cost)
B58: Growth | C58: (+20%) (Multiplier: 1.20) | D58: (+5%) (Multiplier: 1.05) | E58: (0%) (Multiplier: 1.00)
B59: Conservative | C59: (0%) (Multiplier: 1.00) | D59: (0%) (Multiplier: 1.00) | E59: (0%) (Multiplier: 1.00)
B60: Downturn | C60: (-15%) (Multiplier: 0.85) | D60: (-10%) (Multiplier: 0.90) | E60: (+5%) (Multiplier: 1.05)
B63: Metric | C63: Original Totals | D63: Growth Scenario | E63: Conservative Scenario | F63: Downturn Scenario
...

Sheet Growth Scenario Analysis
A1: City | B1: Month | C1: Product_Category | D1: Units_Sold | E1: Unit_Price | F1: Total_Sales | G1: Customer_Count | H1: Variable_Cost_Per_Unit | I1: Contribution_Margin | J1: Units_Growth | K1: Price_Growth | L1: Cost_Growth | M1: Sales_Growth | N1: CM_Growth
A2: Hyderabad | B2: Apr | C2: Smartphones | D2: 870 | E2: 5429.54 | F2: 4723698 | G2: 642 | H2: =$E2*0.6 -> 3257.724 | I2: =($E2-$H2)*$D2 -> 1889479.9 | J2: =D2*1.2 -> 1044 | K2: =E2*1.05 -> 5701.017 | L2: =H2*1 -> 3257.724 | M2: =J2*K2 -> 5951861.7 | N2: =(K2-L2)*J2 -> 2550797.9
A3: Bangalore | B3: Jul | C3: Tablets | D3: 287 | E3: 7156.91 | F3: 2054033 | G3: 224 | H3: =$E3*0.6 -> 4294.146 | I3: =($E3-$H3)*$D3 -> 821613.27 | J3: =D3*1.2 -> 344.4 | K3: =E3*1.05 -> 7514.7555 | L3: =H3*1 -> 4294.146 | M3: =J3*K3 -> 2588081.8 | N3: =(K3-L3)*J3 -> 1109177.9
A4: Ahmedabad | B4: Aug | C4: Tablets | D4: 349 | E4: 6723.95 | F4: 2346658 | G4: 326 | H4: =$E4*0.6 -> 4034.37 | I4: =($E4-$H4)*$D4 -> 938663.42 | J4: =D4*1.2 -> 418.8 | K4: =E4*1.05 -> 7060.1475 | L4: =H4*1 -> 4034.37 | M4: =J4*K4 -> 2956789.8 | N4: =(K4-L4)*J4 -> 1267195.6
A5: Delhi | B5: Dec | C5: Smartphones | D5: 760 | E5: 5268.1 | F5: 4003753 | G5: 589 | H5: =$E5*0.6 -> 3160.86 | I5: =($E5-$H5)*$D5 -> 1601502.4 | J5: =D5*1.2 -> 912 | K5: =E5*1.05 -> 5531.505 | L5: =H5*1 -> 3160.86 | M5: =J5*K5 -> 5044732.6 | N5: =(K5-L5)*J5 -> 2162028.2
A6: Kolkata | B6: Dec | C6: Smartphones | D6: 1160 | E6: 4812.18 | F6: 5582127 | G6: 825 | H6: =$E6*0.6 -> 2887.308 | I6: =($E6-$H6)*$D6 -> 2232851.5 | J6: =D6*1.2 -> 1392 | K6: =E6*1.05 -> 5052.789 | L6: =H6*1 -> 2887.308 | M6: =J6*K6 -> 7033482.3 | N6: =(K6-L6)*J6 -> 3014349.6
A7: Bangalore | B7: Dec | C7: Tablets | D7: 443 | E7: 6881.03 | F7: 3048297 | G7: 375 | H7: =$E7*0.6 -> 4128.618 | I7: =($E7-$H7)*$D7 -> 1219318.5 | J7: =D7*1.2 -> 531.6 | K7: =E7*1.05 -> 7225.0815 | L7: =H7*1 -> 4128.618 | M7: =J7*K7 -> 3840853.3 | N7: =(K7-L7)*J7 -> 1646080
A8: Bangalore | B8: May | C8: Tablets | D8: 334 | E8: 6519.92 | F8: 2177655 | G8: 241 | H8: =$E8*0.6 -> 3911.952 | I8: =($E8-$H8)*$D8 -> 871061.31 | J8: =D8*1.2 -> 400.8 | K8: =E8*1.05 -> 6845.916 | L8: =H8*1 -> 3911.952 | M8: =J8*K8 -> 2743843.1 | N8: =(K8-L8)*J8 -> 1175932.8
A9: Chennai | B9: Dec | C9: Tablets | D9: 463 | E9: 6984.23 | F9: 3233699 | G9: 328 | H9: =$E9*0.6 -> 4190.538 | I9: =($E9-$H9)*$D9 -> 1293479.4 | J9: =D9*1.2 -> 555.6 | K9: =E9*1.05 -> 7333.4415 | L9: =H9*1 -> 4190.538 | M9: =J9*K9 -> 4074460.1 | N9: =(K9-L9)*J9 -> 1746197.2
A10: Mumbai | B10: Apr | C10: Laptops | D10: 203 | E10: 21142.61 | F10: 4291949 | G10: 152 | H10: =$E10*0.6 -> 12685.566 | I10: =($E10-$H10)*$D10 -> 1716779.9 | J10: =D10*1.2 -> 243.6 | K10: =E10*1.05 -> 22199.74 | L10: =H10*1 -> 12685.566 | M10: =J10*K10 -> 5407856.8 | N10: =(K10-L10)*J10 -> 2317652.9
A11: Chennai | B11: Jun | C11: Smartphones | D11: 1001 | E11: 5604.85 | F11: 5610453 | G11: 894 | H11: =$E11*0.6 -> 3362.91 | I11: =($E11-$H11)*$D11 -> 2244181.9 | J11: =D11*1.2 -> 1201.2 | K11: =E11*1.05 -> 5885.0925 | L11: =H11*1 -> 3362.91 | M11: =J11*K11 -> 7069173.1 | N11: =(K11-L11)*J11 -> 3029645.6
A12: Delhi | B12: Oct | C12: Laptops | D12: 113 | E12: 20774.25 | F12: 2347490 | G12: 95 | H12: =$E12*0.6 -> 12464.55 | I12: =($E12-$H12)*$D12 -> 938996.1 | J12: =D12*1.2 -> 135.6 | K12: =E12*1.05 -> 21812.963 | L12: =H12*1 -> 12464.55 | M12: =J12*K12 -> 2957837.7 | N12: =(K12-L12)*J12 -> 1267644.7
A13: Surat | B13: Aug | C13: Smartphones | D13: 937 | E13: 5537.73 | F13: 5188848 | G13: 782 | H13: =$E13*0.6 -> 3322.638 | I13: =($E13-$H13)*$D13 -> 2075541.2 | J13: =D13*1.2 -> 1124.4 | K13: =E13*1.05 -> 5814.6165 | L13: =H13*1 -> 3322.638 | M13: =J13*K13 -> 6537954.8 | N13: =(K13-L13)*J13 -> 2801980.6
... A201: Ahmedabad | B201: Sep | C201: Laptops | D201: 188 | E201: 22244.2 | F201: 4181910 | G201: 161 | H201: =$E201*0.6 -> 13346.52 | I201: =($E201-$H201)*$D201 -> 1672763.8 | J201: =D201*1.2 -> 225.6 | K201: =E201*1.05 -> 23356.41 | L201: =H201*1 -> 13346.52 | M201: =J201*K201 -> 5269206.1 | N201: =(K201-L201)*J201 -> 2258231.2

Sheet Conservative Scenario Analysis
A1: City | B1: Month | C1: Product_Category | D1: Units_Sold | E1: Unit_Price | F1: Total_Sales | G1: Customer_Count | H1: Variable_Cost_Per_Unit | I1: Contribution_Margin | J1: Units_Growth | K1: Price_Growth | L1: Cost_Growth | M1: Sales_Growth | N1: CM_Growth
A2: Hyderabad | B2: Apr | C2: Smartphones | D2: 870 | E2: 5429.54 | F2: 4723698 | G2: 642 | H2: =$E2*0.6 -> 3257.724 | I2: =($E2-$H2)*$D2 -> 1889479.9 | J2: =D2*1 -> 870 | K2: =E2*1 -> 5429.54 | L2: =H2*1 -> 3257.724 | M2: =J2*K2 -> 4723699.8 | N2: =(K2-L2)*J2 -> 1889479.9
A3: Bangalore | B3: Jul | C3: Tablets | D3: 287 | E3: 7156.91 | F3: 2054033 | G3: 224 | H3: =$E3*0.6 -> 4294.146 | I3: =($E3-$H3)*$D3 -> 821613.27 | J3: =D3*1 -> 287 | K3: =E3*1 -> 7156.91 | L3: =H3*1 -> 4294.146 | M3: =J3*K3 -> 2054033.2 | N3: =(K3-L3)*J3 -> 821613.27
A4: Ahmedabad | B4: Aug | C4: Tablets | D4: 349 | E4: 6723.95 | F4: 2346658 | G4: 326 | H4: =$E4*0.6 -> 4034.37 | I4: =($E4-$H4)*$D4 -> 938663.42 | J4: =D4*1 -> 349 | K4: =E4*1 -> 6723.95 | L4: =H4*1 -> 4034.37 | M4: =J4*K4 -> 2346658.5 | N4: =(K4-L4)*J4 -> 938663.42
A5: Delhi | B5: Dec | C5: Smartphones | D5: 760 | E5: 5268.1 | F5: 4003753 | G5: 589 | H5: =$E5*0.6 -> 3160.86 | I5: =($E5-$H5)*$D5 -> 1601502.4 | J5: =D5*1 -> 760 | K5: =E5*1 -> 5268.1 | L5: =H5*1 -> 3160.86 | M5: =J5*K5 -> 4003756 | N5: =(K5-L5)*J5 -> 1601502.4
A6: Kolkata | B6: Dec | C6: Smartphones | D6: 1160 | E6: 4812.18 | F6: 5582127 | G6: 825 | H6: =$E6*0.6 -> 2887.308 | I6: =($E6-$H6)*$D6 -> 2232851.5 | J6: =D6*1 -> 1160 | K6: =E6*1 -> 4812.18 | L6: =H6*1 -> 2887.308 | M6: =J6*K6 -> 5582128.8 | N6: =(K6-L6)*J6 -> 2232851.5
A7: Bangalore | B7: Dec | C7: Tablets | D7: 443 | E7: 6881.03 | F7: 3048297 | G7: 375 | H7: =$E7*0.6 -> 4128.618 | I7: =($E7-$H7)*$D7 -> 1219318.5 | J7: =D7*1 -> 443 | K7: =E7*1 -> 6881.03 | L7: =H7*1 -> 4128.618 | M7: =J7*K7 -> 3048296.3 | N7: =(K7-L7)*J7 -> 1219318.5
A8: Bangalore | B8: May | C8: Tablets | D8: 334 | E8: 6519.92 | F8: 2177655 | G8: 241 | H8: =$E8*0.6 -> 3911.952 | I8: =($E8-$H8)*$D8 -> 871061.31 | J8: =D8*1 -> 334 | K8: =E8*1 -> 6519.92 | L8: =H8*1 -> 3911.952 | M8: =J8*K8 -> 2177653.3 | N8: =(K8-L8)*J8 -> 871061.31
A9: Chennai | B9: Dec | C9: Tablets | D9: 463 | E9: 6984.23 | F9: 3233699 | G9: 328 | H9: =$E9*0.6 -> 4190.538 | I9: =($E9-$H9)*$D9 -> 1293479.4 | J9: =D9*1 -> 463 | K9: =E9*1 -> 6984.23 | L9: =H9*1 -> 4190.538 | M9: =J9*K9 -> 3233698.5 | N9: =(K9-L9)*J9 -> 1293479.4
A10: Mumbai | B10: Apr | C10: Laptops | D10: 203 | E10: 21142.61 | F10: 4291949 | G10: 152 | H10: =$E10*0.6 -> 12685.566 | I10: =($E10-$H10)*$D10 -> 1716779.9 | J10: =D10*1 -> 203 | K10: =E10*1 -> 21142.61 | L10: =H10*1 -> 12685.566 | M10: =J10*K10 -> 4291949.8 | N10: =(K10-L10)*J10 -> 1716779.9
A11: Chennai | B11: Jun | C11: Smartphones | D11: 1001 | E11: 5604.85 | F11: 5610453 | G11: 894 | H11: =$E11*0.6 -> 3362.91 | I11: =($E11-$H11)*$D11 -> 2244181.9 | J11: =D11*1 -> 1001 | K11: =E11*1 -> 5604.85 | L11: =H11*1 -> 3362.91 | M11: =J11*K11 -> 5610454.8 | N11: =(K11-L11)*J11 -> 2244181.9
A12: Delhi | B12: Oct | C12: Laptops | D12: 113 | E12: 20774.25 | F12: 2347490 | G12: 95 | H12: =$E12*0.6 -> 12464.55 | I12: =($E12-$H12)*$D12 -> 938996.1 | J12: =D12*1 -> 113 | K12: =E12*1 -> 20774.25 | L12: =H12*1 -> 12464.55 | M12: =J12*K12 -> 2347490.2 | N12: =(K12-L12)*J12 -> 938996.1
A13: Surat | B13: Aug | C13: Smartphones | D13: 937 | E13: 5537.73 | F13: 5188848 | G13: 782 | H13: =$E13*0.6 -> 3322.638 | I13: =($E13-$H13)*$D13 -> 2075541.2 | J13: =D13*1 -> 937 | K13: =E13*1 -> 5537.73 | L13: =H13*1 -> 3322.638 | M13: =J13*K13 -> 5188853 | N13: =(K13-L13)*J13 -> 2075541.2
... A201: Ahmedabad | B201: Sep | C201: Laptops | D201: 188 | E201: 22244.2 | F201: 4181910 | G201: 161 | H201: =$E201*0.6 -> 13346.52 | I201: =($E201-$H201)*$D201 -> 1672763.8 | J201: =D201*1 -> 188 | K201: =E201*1 -> 22244.2 | L201: =H201*1 -> 13346.52 | M201: =J201*K201 -> 4181909.6 | N201: =(K201-L201)*J201 -> 1672763.8

Sheet Downturn Scenario Analysis
A1: City | B1: Month | C1: Product_Category | D1: Units_Sold | E1: Unit_Price | F1: Total_Sales | G1: Customer_Count | H1: Variable_Cost_Per_Unit | I1: Contribution_Margin | J1: Units_Growth | K1: Price_Growth | L1: Cost_Growth | M1: Sales_Growth | N1: CM_Growth
A2: Hyderabad | B2: Apr | C2: Smartphones | D2: 870 | E2: 5429.54 | F2: 4723698 | G2: 642 | H2: =$E2*0.6 -> 3257.724 | I2: =($E2-$H2)*$D2 -> 1889479.9 | J2: =D2*0.85 -> 739.5 | K2: =E2*0.9 -> 4886.586 | L2: =H2*1.05 -> 3420.6102 | M2: =J2*K2 -> 3613630.3 | N2: =(K2-L2)*J2 -> 1084089.1
A3: Bangalore | B3: Jul | C3: Tablets | D3: 287 | E3: 7156.91 | F3: 2054033 | G3: 224 | H3: =$E3*0.6 -> 4294.146 | I3: =($E3-$H3)*$D3 -> 821613.27 | J3: =D3*0.85 -> 243.95 | K3: =E3*0.9 -> 6441.219 | L3: =H3*1.05 -> 4508.8533 | M3: =J3*K3 -> 1571335.4 | N3: =(K3-L3)*J3 -> 471400.61
A4: Ahmedabad | B4: Aug | C4: Tablets | D4: 349 | E4: 6723.95 | F4: 2346658 | G4: 326 | H4: =$E4*0.6 -> 4034.37 | I4: =($E4-$H4)*$D4 -> 938663.42 | J4: =D4*0.85 -> 296.65 | K4: =E4*0.9 -> 6051.555 | L4: =H4*1.05 -> 4236.0885 | M4: =J4*K4 -> 1795193.8 | N4: =(K4-L4)*J4 -> 538558.14
A5: Delhi | B5: Dec | C5: Smartphones | D5: 760 | E5: 5268.1 | F5: 4003753 | G5: 589 | H5: =$E5*0.6 -> 3160.86 | I5: =($E5-$H5)*$D5 -> 1601502.4 | J5: =D5*0.85 -> 646 | K5: =E5*0.9 -> 4741.29 | L5: =H5*1.05 -> 3318.903 | M5: =J5*K5 -> 3062873.3 | N5: =(K5-L5)*J5 -> 918862
A6: Kolkata | B6: Dec | C6: Smartphones | D6: 1160 | E6: 4812.18 | F6: 5582127 | G6: 825 | H6: =$E6*0.6 -> 2887.308 | I6: =($E6-$H6)*$D6 -> 2232851.5 | J6: =D6*0.85 -> 986 | K6: =E6*0.9 -> 4330.962 | L6: =H6*1.05 -> 3031.6734 | M6: =J6*K6 -> 4270328.5 | N6: =(K6-L6)*J6 -> 1281098.6
A7: Bangalore | B7: Dec | C7: Tablets | D7: 443 | E7: 6881.03 | F7: 3048297 | G7: 375 | H7: =$E7*0.6 -> 4128.618 | I7: =($E7-$H7)*$D7 -> 1219318.5 | J7: =D7*0.85 -> 376.55 | K7: =E7*0.9 -> 6192.927 | L7: =H7*1.05 -> 4335.0489 | M7: =J7*K7 -> 2331946.7 | N7: =(K7-L7)*J7 -> 699584
A8: Bangalore | B8: May | C8: Tablets | D8: 334 | E8: 6519.92 | F8: 2177655 | G8: 241 | H8: =$E8*0.6 -> 3911.952 | I8: =($E8-$H8)*$D8 -> 871061.31 | J8: =D8*0.85 -> 283.9 | K8: =E8*0.9 -> 5867.928 | L8: =H8*1.05 -> 4107.5496 | M8: =J8*K8 -> 1665904.8 | N8: =(K8-L8)*J8 -> 499771.43
A9: Chennai | B9: Dec | C9: Tablets | D9: 463 | E9: 6984.23 | F9: 3233699 | G9: 328 | H9: =$E9*0.6 -> 4190.538 | I9: =($E9-$H9)*$D9 -> 1293479.4 | J9: =D9*0.85 -> 393.55 | K9: =E9*0.9 -> 6285.807 | L9: =H9*1.05 -> 4400.0649 | M9: =J9*K9 -> 2473779.3 | N9: =(K9-L9)*J9 -> 742133.8
A10: Mumbai | B10: Apr | C10: Laptops | D10: 203 | E10: 21142.61 | F10: 4291949 | G10: 152 | H10: =$E10*0.6 -> 12685.566 | I10: =($E10-$H10)*$D10 -> 1716779.9 | J10: =D10*0.85 -> 172.55 | K10: =E10*0.9 -> 19028.349 | L10: =H10*1.05 -> 13319.844 | M10: =J10*K10 -> 3283341.6 | N10: =(K10-L10)*J10 -> 985002.49
A11: Chennai | B11: Jun | C11: Smartphones | D11: 1001 | E11: 5604.85 | F11: 5610453 | G11: 894 | H11: =$E11*0.6 -> 3362.91 | I11: =($E11-$H11)*$D11 -> 2244181.9 | J11: =D11*0.85 -> 850.85 | K11: =E11*0.9 -> 5044.365 | L11: =H11*1.05 -> 3531.0555 | M11: =J11*K11 -> 4291998 | N11: =(K11-L11)*J11 -> 1287599.4
A12: Delhi | B12: Oct | C12: Laptops | D12: 113 | E12: 20774.25 | F12: 2347490 | G12: 95 | H12: =$E12*0.6 -> 12464.55 | I12: =($E12-$H12)*$D12 -> 938996.1 | J12: =D12*0.85 -> 96.05 | K12: =E12*0.9 -> 18696.825 | L12: =H12*1.05 -> 13087.778 | M12: =J12*K12 -> 1795830 | N12: =(K12-L12)*J12 -> 538749.01
A13: Surat | B13: Aug | C13: Smartphones | D13: 937 | E13: 5537.73 | F13: 5188848 | G13: 782 | H13: =$E13*0.6 -> 3322.638 | I13: =($E13-$H13)*$D13 -> 2075541.2 | J13: =D13*0.85 -> 796.45 | K13: =E13*0.9 -> 4983.957 | L13: =H13*1.05 -> 3488.7699 | M13: =J13*K13 -> 3969472.6 | N13: =(K13-L13)*J13 -> 1190841.8
... A201: Ahmedabad | B201: Sep | C201: Laptops | D201: 188 | E201: 22244.2 | F201: 4181910 | G201: 161 | H201: =$E201*0.6 -> 13346.52 | I201: =($E201-$H201)*$D201 -> 1672763.8 | J201: =D201*0.85 -> 159.8 | K201: =E201*0.9 -> 20019.78 | L201: =H201*1.05 -> 14013.846 | M201: =J201*K201 -> 3199160.8 | N201: =(K201-L201)*J201 -> 959748.25

Sheet What If-Best Case Scenario
A1: City | B1: Month | C1: Product_Category | D1: Units_Sold | E1: Unit_Price | F1: Total_Sales | G1: Customer_Count | H1: Variable_Cost_Per_Unit | I1: Contribution_Margin | J1: New_Unit_Sold | K1: New_Unit_Price | L1: New_Total_Sales | M1: New_Contribution_Margin
A2: Hyderabad | B2: Apr | C2: Smartphones | D2: 870 | E2: 5429.54 | F2: 4723698 | G2: 642 | H2: =$E2*0.6 -> 3257.724 | I2: =($E2-$H2)*$D2 -> 1889479.9 | J2: =IF(AND(C2="Smartphones", OR(B2="Mar", B2="Jun", B2="Sep")), D2*1.25, D2) -> 870 | K2: =IF(AND(C2="Smartphones", OR(B2="Mar", B2="Jun", B2="Sep")), E2*0.9, E2) -> 5429.54 | L2: =$K2*$J2 -> 4723699.8 | M2: =(K2-H2)*J2 -> 1889479.9
A3: Bangalore | B3: Jul | C3: Tablets | D3: 287 | E3: 7156.91 | F3: 2054033 | G3: 224 | H3: =$E3*0.6 -> 4294.146 | I3: =($E3-$H3)*$D3 -> 821613.27 | J3: =IF(AND(C3="Smartphones", OR(B3="Mar", B3="Jun", B3="Sep")), D3*1.25, D3) -> 287 | K3: =IF(AND(C3="Smartphones", OR(B3="Mar", B3="Jun", B3="Sep")), E3*0.9, E3) -> 7156.91 | L3: =$K3*$J3 -> 2054033.2 | M3: =(K3-H3)*J3 -> 821613.27
A4: Ahmedabad | B4: Aug | C4: Tablets | D4: 349 | E4: 6723.95 | F4: 2346658 | G4: 326 | H4: =$E4*0.6 -> 4034.37 | I4: =($E4-$H4)*$D4 -> 938663.42 | J4: =IF(AND(C4="Smartphones", OR(B4="Mar", B4="Jun", B4="Sep")), D4*1.25, D4) -> 349 | K4: =IF(AND(C4="Smartphones", OR(B4="Mar", B4="Jun", B4="Sep")), E4*0.9, E4) -> 6723.95 | L4: =$K4*$J4 -> 2346658.5 | M4: =(K4-H4)*J4 -> 938663.42
A5: Delhi | B5: Dec | C5: Smartphones | D5: 760 | E5: 5268.1 | F5: 4003753 | G5: 589 | H5: =$E5*0.6 -> 3160.86 | I5: =($E5-$H5)*$D5 -> 1601502.4 | J5: =IF(AND(C5="Smartphones", OR(B5="Mar", B5="Jun", B5="Sep")), D5*1.25, D5) -> 760 | K5: =IF(AND(C5="Smartphones", OR(B5="Mar", B5="Jun", B5="Sep")), E5*0.9, E5) -> 5268.1 | L5: =$K5*$J5 -> 4003756 | M5: =(K5-H5)*J5 -> 1601502.4
A6: Kolkata | B6: Dec | C6: Smartphones | D6: 1160 | E6: 4812.18 | F6: 5582127 | G6: 825 | H6: =$E6*0.6 -> 2887.308 | I6: =($E6-$H6)*$D6 -> 2232851.5 | J6: =IF(AND(C6="Smartphones", OR(B6="Mar", B6="Jun", B6="Sep")), D6*1.25, D6) -> 1160 | K6: =IF(AND(C6="Smartphones", OR(B6="Mar", B6="Jun", B6="Sep")), E6*0.9, E6) -> 4812.18 | L6: =$K6*$J6 -> 5582128.8 | M6: =(K6-H6)*J6 -> 2232851.5
A7: Bangalore | B7: Dec | C7: Tablets | D7: 443 | E7: 6881.03 | F7: 3048297 | G7: 375 | H7: =$E7*0.6 -> 4128.618 | I7: =($E7-$H7)*$D7 -> 1219318.5 | J7: =IF(AND(C7="Smartphones", OR(B7="Mar", B7="Jun", B7="Sep")), D7*1.25, D7) -> 443 | K7: =IF(AND(C7="Smartphones", OR(B7="Mar", B7="Jun", B7="Sep")), E7*0.9, E7) -> 6881.03 | L7: =$K7*$J7 -> 3048296.3 | M7: =(K7-H7)*J7 -> 1219318.5
A8: Bangalore | B8: May | C8: Tablets | D8: 334 | E8: 6519.92 | F8: 2177655 | G8: 241 | H8: =$E8*0.6 -> 3911.952 | I8: =($E8-$H8)*$D8 -> 871061.31 | J8: =IF(AND(C8="Smartphones", OR(B8="Mar", B8="Jun", B8="Sep")), D8*1.25, D8) -> 334 | K8: =IF(AND(C8="Smartphones", OR(B8="Mar", B8="Jun", B8="Sep")), E8*0.9, E8) -> 6519.92 | L8: =$K8*$J8 -> 2177653.3 | M8: =(K8-H8)*J8 -> 871061.31
A9: Chennai | B9: Dec | C9: Tablets | D9: 463 | E9: 6984.23 | F9: 3233699 | G9: 328 | H9: =$E9*0.6 -> 4190.538 | I9: =($E9-$H9)*$D9 -> 1293479.4 | J9: =IF(AND(C9="Smartphones", OR(B9="Mar", B9="Jun", B9="Sep")), D9*1.25, D9) -> 463 | K9: =IF(AND(C9="Smartphones", OR(B9="Mar", B9="Jun", B9="Sep")), E9*0.9, E9) -> 6984.23 | L9: =$K9*$J9 -> 3233698.5 | M9: =(K9-H9)*J9 -> 1293479.4
A10: Mumbai | B10: Apr | C10: Laptops | D10: 203 | E10: 21142.61 | F10: 4291949 | G10: 152 | H10: =$E10*0.6 -> 12685.566 | I10: =($E10-$H10)*$D10 -> 1716779.9 | J10: =IF(AND(C10="Smartphones", OR(B10="Mar", B10="Jun", B10="Sep")), D10*1.25, D10) -> 203 | K10: =IF(AND(C10="Smartphones", OR(B10="Mar", B10="Jun", B10="Sep")), E10*0.9, E10) -> 21142.61 | L10: =$K10*$J10 -> 4291949.8 | M10: =(K10-H10)*J10 -> 1716779.9
A11: Chennai | B11: Jun | C11: Smartphones | D11: 1001 | E11: 5604.85 | F11: 5610453 | G11: 894 | H11: =$E11*0.6 -> 3362.91 | I11: =($E11-$H11)*$D11 -> 2244181.9 | J11: =IF(AND(C11="Smartphones", OR(B11="Mar", B11="Jun", B11="Sep")), D11*1.25, D11) -> 1251.25 | K11: =IF(AND(C11="Smartphones", OR(B11="Mar", B11="Jun", B11="Sep")), E11*0.9, E11) -> 5044.365 | L11: =$K11*$J11 -> 6311761.7 | M11: =(K11-H11)*J11 -> 2103920.6
A12: Delhi | B12: Oct | C12: Laptops | D12: 113 | E12: 20774.25 | F12: 2347490 | G12: 95 | H12: =$E12*0.6 -> 12464.55 | I12: =($E12-$H12)*$D12 -> 938996.1 | J12: =IF(AND(C12="Smartphones", OR(B12="Mar", B12="Jun", B12="Sep")), D12*1.25, D12) -> 113 | K12: =IF(AND(C12="Smartphones", OR(B12="Mar", B12="Jun", B12="Sep")), E12*0.9, E12) -> 20774.25 | L12: =$K12*$J12 -> 2347490.2 | M12: =(K12-H12)*J12 -> 938996.1
A13: Surat | B13: Aug | C13: Smartphones | D13: 937 | E13: 5537.73 | F13: 5188848 | G13: 782 | H13: =$E13*0.6 -> 3322.638 | I13: =($E13-$H13)*$D13 -> 2075541.2 | J13: =IF(AND(C13="Smartphones", OR(B13="Mar", B13="Jun", B13="Sep")), D13*1.25, D13) -> 937 | K13: =IF(AND(C13="Smartphones", OR(B13="Mar", B13="Jun", B13="Sep")), E13*0.9, E13) -> 5537.73 | L13: =$K13*$J13 -> 5188853 | M13: =(K13-H13)*J13 -> 2075541.2
... A201: Ahmedabad | B201: Sep | C201: Laptops | D201: 188 | E201: 22244.2 | F201: 4181910 | G201: 161 | H201: =$E201*0.6 -> 13346.52 | I201: =($E201-$H201)*$D201 -> 1672763.8 | J201: =IF(AND(C201="Smartphones", OR(B201="Mar", B201="Jun", B201="Sep")), D201*1.25, D201) -> 188 | K201: =IF(AND(C201="Smartphones", OR(B201="Mar", B201="Jun", B201="Sep")), E201*0.9, E201) -> 22244.2 | L201: =$K201*$J201 -> 4181909.6 | M201: =(K201-H201)*J201 -> 1672763.8

Sheet What If- Expected Case Scenario
A1: City | B1: Month | C1: Product_Category | D1: Units_Sold | E1: Unit_Price | F1: Total_Sales | G1: Customer_Count | H1: Variable_Cost_Per_Unit | I1: Contribution_Margin | J1: New_Unit_Sold | K1: New_Unit_Price | L1: New_Total_Sales | M1: New_Contribution_Margin
A2: Hyderabad | B2: Apr | C2: Smartphones | D2: 870 | E2: 5429.54 | F2: 4723698 | G2: 642 | H2: =$E2*0.6 -> 3257.724 | I2: =($E2-$H2)*$D2 -> 1889479.9 | J2: =IF(AND(C2="Smartphones", OR(B2="Mar", B2="Jun", B2="Sep")), D2*1.1, D2) -> 870 | K2: =IF(AND(C2="Smartphones", OR(B2="Mar", B2="Jun", B2="Sep")), E2*0.9, E2) -> 5429.54 | L2: =$K2*$J2 -> 4723699.8 | M2: =(K2-H2)*J2 -> 1889479.9
A3: Bangalore | B3: Jul | C3: Tablets | D3: 287 | E3: 7156.91 | F3: 2054033 | G3: 224 | H3: =$E3*0.6 -> 4294.146 | I3: =($E3-$H3)*$D3 -> 821613.27 | J3: =IF(AND(C3="Smartphones", OR(B3="Mar", B3="Jun", B3="Sep")), D3*1.1, D3) -> 287 | K3: =IF(AND(C3="Smartphones", OR(B3="Mar", B3="Jun", B3="Sep")), E3*0.9, E3) -> 7156.91 | L3: =$K3*$J3 -> 2054033.2 | M3: =(K3-H3)*J3 -> 821613.27
A4: Ahmedabad | B4: Aug | C4: Tablets | D4: 349 | E4: 6723.95 | F4: 2346658 | G4: 326 | H4: =$E4*0.6 -> 4034.37 | I4: =($E4-$H4)*$D4 -> 938663.42 | J4: =IF(AND(C4="Smartphones", OR(B4="Mar", B4="Jun", B4="Sep")), D4*1.1, D4) -> 349 | K4: =IF(AND(C4="Smartphones", OR(B4="Mar", B4="Jun", B4="Sep")), E4*0.9, E4) -> 6723.95 | L4: =$K4*$J4 -> 2346658.5 | M4: =(K4-H4)*J4 -> 938663.42
A5: Delhi | B5: Dec | C5: Smartphones | D5: 760 | E5: 5268.1 | F5: 4003753 | G5: 589 | H5: =$E5*0.6 -> 3160.86 | I5: =($E5-$H5)*$D5 -> 1601502.4 | J5: =IF(AND(C5="Smartphones", OR(B5="Mar", B5="Jun", B5="Sep")), D5*1.1, D5) -> 760 | K5: =IF(AND(C5="Smartphones", OR(B5="Mar", B5="Jun", B5="Sep")), E5*0.9, E5) -> 5268.1 | L5: =$K5*$J5 -> 4003756 | M5: =(K5-H5)*J5 -> 1601502.4
A6: Kolkata | B6: Dec | C6: Smartphones | D6: 1160 | E6: 4812.18 | F6: 5582127 | G6: 825 | H6: =$E6*0.6 -> 2887.308 | I6: =($E6-$H6)*$D6 -> 2232851.5 | J6: =IF(AND(C6="Smartphones", OR(B6="Mar", B6="Jun", B6="Sep")), D6*1.1, D6) -> 1160 | K6: =IF(AND(C6="Smartphones", OR(B6="Mar", B6="Jun", B6="Sep")), E6*0.9, E6) -> 4812.18 | L6: =$K6*$J6 -> 5582128.8 | M6: =(K6-H6)*J6 -> 2232851.5
A7: Bangalore | B7: Dec | C7: Tablets | D7: 443 | E7: 6881.03 | F7: 3048297 | G7: 375 | H7: =$E7*0.6 -> 4128.618 | I7: =($E7-$H7)*$D7 -> 1219318.5 | J7: =IF(AND(C7="Smartphones", OR(B7="Mar", B7="Jun", B7="Sep")), D7*1.1, D7) -> 443 | K7: =IF(AND(C7="Smartphones", OR(B7="Mar", B7="Jun", B7="Sep")), E7*0.9, E7) -> 6881.03 | L7: =$K7*$J7 -> 3048296.3 | M7: =(K7-H7)*J7 -> 1219318.5
A8: Bangalore | B8: May | C8: Tablets | D8: 334 | E8: 6519.92 | F8: 2177655 | G8: 241 | H8: =$E8*0.6 -> 3911.952 | I8: =($E8-$H8)*$D8 -> 871061.31 | J8: =IF(AND(C8="Smartphones", OR(B8="Mar", B8="Jun", B8="Sep")), D8*1.1, D8) -> 334 | K8: =IF(AND(C8="Smartphones", OR(B8="Mar", B8="Jun", B8="Sep")), E8*0.9, E8) -> 6519.92 | L8: =$K8*$J8 -> 2177653.3 | M8: =(K8-H8)*J8 -> 871061.31
A9: Chennai | B9: Dec | C9: Tablets | D9: 463 | E9: 6984.23 | F9: 3233699 | G9: 328 | H9: =$E9*0.6 -> 4190.538 | I9: =($E9-$H9)*$D9 -> 1293479.4 | J9: =IF(AND(C9="Smartphones", OR(B9="Mar", B9="Jun", B9="Sep")), D9*1.1, D9) -> 463 | K9: =IF(AND(C9="Smartphones", OR(B9="Mar", B9="Jun", B9="Sep")), E9*0.9, E9) -> 6984.23 | L9: =$K9*$J9 -> 3233698.5 | M9: =(K9-H9)*J9 -> 1293479.4
A10: Mumbai | B10: Apr | C10: Laptops | D10: 203 | E10: 21142.61 | F10: 4291949 | G10: 152 | H10: =$E10*0.6 -> 12685.566 | I10: =($E10-$H10)*$D10 -> 1716779.9 | J10: =IF(AND(C10="Smartphones", OR(B10="Mar", B10="Jun", B10="Sep")), D10*1.1, D10) -> 203 | K10: =IF(AND(C10="Smartphones", OR(B10="Mar", B10="Jun", B10="Sep")), E10*0.9, E10) -> 21142.61 | L10: =$K10*$J10 -> 4291949.8 | M10: =(K10-H10)*J10 -> 1716779.9
A11: Chennai | B11: Jun | C11: Smartphones | D11: 1001 | E11: 5604.85 | F11: 5610453 | G11: 894 | H11: =$E11*0.6 -> 3362.91 | I11: =($E11-$H11)*$D11 -> 2244181.9 | J11: =IF(AND(C11="Smartphones", OR(B11="Mar", B11="Jun", B11="Sep")), D11*1.1, D11) -> 1101.1 | K11: =IF(AND(C11="Smartphones", OR(B11="Mar", B11="Jun", B11="Sep")), E11*0.9, E11) -> 5044.365 | L11: =$K11*$J11 -> 5554350.3 | M11: =(K11-H11)*J11 -> 1851450.1
A12: Delhi | B12: Oct | C12: Laptops | D12: 113 | E12: 20774.25 | F12: 2347490 | G12: 95 | H12: =$E12*0.6 -> 12464.55 | I12: =($E12-$H12)*$D12 -> 938996.1 | J12: =IF(AND(C12="Smartphones", OR(B12="Mar", B12="Jun", B12="Sep")), D12*1.1, D12) -> 113 | K12: =IF(AND(C12="Smartphones", OR(B12="Mar", B12="Jun", B12="Sep")), E12*0.9, E12) -> 20774.25 | L12: =$K12*$J12 -> 2347490.2 | M12: =(K12-H12)*J12 -> 938996.1
A13: Surat | B13: Aug | C13: Smartphones | D13: 937 | E13: 5537.73 | F13: 5188848 | G13: 782 | H13: =$E13*0.6 -> 3322.638 | I13: =($E13-$H13)*$D13 -> 2075541.2 | J13: =IF(AND(C13="Smartphones", OR(B13="Mar", B13="Jun", B13="Sep")), D13*1.1, D13) -> 937 | K13: =IF(AND(C13="Smartphones", OR(B13="Mar", B13="Jun", B13="Sep")), E13*0.9, E13) -> 5537.73 | L13: =$K13*$J13 -> 5188853 | M13: =(K13-H13)*J13 -> 2075541.2
... A201: Ahmedabad | B201: Sep | C201: Laptops | D201: 188 | E201: 22244.2 | F201: 4181910 | G201: 161 | H201: =$E201*0.6 -> 13346.52 | I201: =($E201-$H201)*$D201 -> 1672763.8 | J201: =IF(AND(C201="Smartphones", OR(B201="Mar", B201="Jun", B201="Sep")), D201*1.1, D201) -> 188 | K201: =IF(AND(C201="Smartphones", OR(B201="Mar", B201="Jun", B201="Sep")), E201*0.9, E201) -> 22244.2 | L201: =$K201*$J201 -> 4181909.6 | M201: =(K201-H201)*J201 -> 1672763.8

Sheet What If- Worst Case Scenario
A1: City | B1: Month | C1: Product_Category | D1: Units_Sold | E1: Unit_Price | F1: Total_Sales | G1: Customer_Count | H1: Variable_Cost_Per_Unit | I1: Contribution_Margin | J1: New_Unit_Sold | K1: New_Unit_Price | L1: New_Total_Sales | M1: New_Contribution_Margin
A2: Hyderabad | B2: Apr | C2: Smartphones | D2: 870 | E2: 5429.54 | F2: 4723698 | G2: 642 | H2: =$E2*0.6 -> 3257.724 | I2: =($E2-$H2)*$D2 -> 1889479.9 | J2: =IF(AND(C2="Smartphones", OR(B2="Mar", B2="Jun", B2="Sep")), D2*1, D2) -> 870 | K2: =IF(AND(C2="Smartphones", OR(B2="Mar", B2="Jun", B2="Sep")), E2*0.9, E2) -> 5429.54 | L2: =$K2*$J2 -> 4723699.8 | M2: =(K2-H2)*J2 -> 1889479.9
A3: Bangalore | B3: Jul | C3: Tablets | D3: 287 | E3: 7156.91 | F3: 2054033 | G3: 224 | H3: =$E3*0.6 -> 4294.146 | I3: =($E3-$H3)*$D3 -> 821613.27 | J3: =IF(AND(C3="Smartphones", OR(B3="Mar", B3="Jun", B3="Sep")), D3*1, D3) -> 287 | K3: =IF(AND(C3="Smartphones", OR(B3="Mar", B3="Jun", B3="Sep")), E3*0.9, E3) -> 7156.91 | L3: =$K3*$J3 -> 2054033.2 | M3: =(K3-H3)*J3 -> 821613.27
A4: Ahmedabad | B4: Aug | C4: Tablets | D4: 349 | E4: 6723.95 | F4: 2346658 | G4: 326 | H4: =$E4*0.6 -> 4034.37 | I4: =($E4-$H4)*$D4 -> 938663.42 | J4: =IF(AND(C4="Smartphones", OR(B4="Mar", B4="Jun", B4="Sep")), D4*1, D4) -> 349 | K4: =IF(AND(C4="Smartphones", OR(B4="Mar", B4="Jun", B4="Sep")), E4*0.9, E4) -> 6723.95 | L4: =$K4*$J4 -> 2346658.5 | M4: =(K4-H4)*J4 -> 938663.42
A5: Delhi | B5: Dec | C5: Smartphones | D5: 760 | E5: 5268.1 | F5: 4003753 | G5: 589 | H5: =$E5*0.6 -> 3160.86 | I5: =($E5-$H5)*$D5 -> 1601502.4 | J5: =IF(AND(C5="Smartphones", OR(B5="Mar", B5="Jun", B5="Sep")), D5*1, D5) -> 760 | K5: =IF(AND(C5="Smartphones", OR(B5="Mar", B5="Jun", B5="Sep")), E5*0.9, E5) -> 5268.1 | L5: =$K5*$J5 -> 4003756 | M5: =(K5-H5)*J5 -> 1601502.4
A6: Kolkata | B6: Dec | C6: Smartphones | D6: 1160 | E6: 4812.18 | F6: 5582127 | G6: 825 | H6: =$E6*0.6 -> 2887.308 | I6: =($E6-$H6)*$D6 -> 2232851.5 | J6: =IF(AND(C6="Smartphones", OR(B6="Mar", B6="Jun", B6="Sep")), D6*1, D6) -> 1160 | K6: =IF(AND(C6="Smartphones", OR(B6="Mar", B6="Jun", B6="Sep")), E6*0.9, E6) -> 4812.18 | L6: =$K6*$J6 -> 5582128.8 | M6: =(K6-H6)*J6 -> 2232851.5
A7: Bangalore | B7: Dec | C7: Tablets | D7: 443 | E7: 6881.03 | F7: 3048297 | G7: 375 | H7: =$E7*0.6 -> 4128.618 | I7: =($E7-$H7)*$D7 -> 1219318.5 | J7: =IF(AND(C7="Smartphones", OR(B7="Mar", B7="Jun", B7="Sep")), D7*1, D7) -> 443 | K7: =IF(AND(C7="Smartphones", OR(B7="Mar", B7="Jun", B7="Sep")), E7*0.9, E7) -> 6881.03 | L7: =$K7*$J7 -> 3048296.3 | M7: =(K7-H7)*J7 -> 1219318.5
A8: Bangalore | B8: May | C8: Tablets | D8: 334 | E8: 6519.92 | F8: 2177655 | G8: 241 | H8: =$E8*0.6 -> 3911.952 | I8: =($E8-$H8)*$D8 -> 871061.31 | J8: =IF(AND(C8="Smartphones", OR(B8="Mar", B8="Jun", B8="Sep")), D8*1, D8) -> 334 | K8: =IF(AND(C8="Smartphones", OR(B8="Mar", B8="Jun", B8="Sep")), E8*0.9, E8) -> 6519.92 | L8: =$K8*$J8 -> 2177653.3 | M8: =(K8-H8)*J8 -> 871061.31
A9: Chennai | B9: Dec | C9: Tablets | D9: 463 | E9: 6984.23 | F9: 3233699 | G9: 328 | H9: =$E9*0.6 -> 4190.538 | I9: =($E9-$H9)*$D9 -> 1293479.4 | J9: =IF(AND(C9="Smartphones", OR(B9="Mar", B9="Jun", B9="Sep")), D9*1, D9) -> 463 | K9: =IF(AND(C9="Smartphones", OR(B9="Mar", B9="Jun", B9="Sep")), E9*0.9, E9) -> 6984.23 | L9: =$K9*$J9 -> 3233698.5 | M9: =(K9-H9)*J9 -> 1293479.4
A10: Mumbai | B10: Apr | C10: Laptops | D10: 203 | E10: 21142.61 | F10: 4291949 | G10: 152 | H10: =$E10*0.6 -> 12685.566 | I10: =($E10-$H10)*$D10 -> 1716779.9 | J10: =IF(AND(C10="Smartphones", OR(B10="Mar", B10="Jun", B10="Sep")), D10*1, D10) -> 203 | K10: =IF(AND(C10="Smartphones", OR(B10="Mar", B10="Jun", B10="Sep")), E10*0.9, E10) -> 21142.61 | L10: =$K10*$J10 -> 4291949.8 | M10: =(K10-H10)*J10 -> 1716779.9
A11: Chennai | B11: Jun | C11: Smartphones | D11: 1001 | E11: 5604.85 | F11: 5610453 | G11: 894 | H11: =$E11*0.6 -> 3362.91 | I11: =($E11-$H11)*$D11 -> 2244181.9 | J11: =IF(AND(C11="Smartphones", OR(B11="Mar", B11="Jun", B11="Sep")), D11*1, D11) -> 1001 | K11: =IF(AND(C11="Smartphones", OR(B11="Mar", B11="Jun", B11="Sep")), E11*0.9, E11) -> 5044.365 | L11: =$K11*$J11 -> 5049409.4 | M11: =(K11-H11)*J11 -> 1683136.5
A12: Delhi | B12: Oct | C12: Laptops | D12: 113 | E12: 20774.25 | F12: 2347490 | G12: 95 | H12: =$E12*0.6 -> 12464.55 | I12: =($E12-$H12)*$D12 -> 938996.1 | J12: =IF(AND(C12="Smartphones", OR(B12="Mar", B12="Jun", B12="Sep")), D12*1, D12) -> 113 | K12: =IF(AND(C12="Smartphones", OR(B12="Mar", B12="Jun", B12="Sep")), E12*0.9, E12) -> 20774.25 | L12: =$K12*$J12 -> 2347490.2 | M12: =(K12-H12)*J12 -> 938996.1
A13: Surat | B13: Aug | C13: Smartphones | D13: 937 | E13: 5537.73 | F13: 5188848 | G13: 782 | H13: =$E13*0.6 -> 3322.638 | I13: =($E13-$H13)*$D13 -> 2075541.2 | J13: =IF(AND(C13="Smartphones", OR(B13="Mar", B13="Jun", B13="Sep")), D13*1, D13) -> 937 | K13: =IF(AND(C13="Smartphones", OR(B13="Mar", B13="Jun", B13="Sep")), E13*0.9, E13) -> 5537.73 | L13: =$K13*$J13 -> 5188853 | M13: =(K13-H13)*J13 -> 2075541.2
... A201: Ahmedabad | B201: Sep | C201: Laptops | D201: 188 | E201: 22244.2 | F201: 4181910 | G201: 161 | H201: =$E201*0.6 -> 13346.52 | I201: =($E201-$H201)*$D201 -> 1672763.8 | J201: =IF(AND(C201="Smartphones", OR(B201="Mar", B201="Jun", B201="Sep")), D201*1, D201) -> 188 | K201: =IF(AND(C201="Smartphones", OR(B201="Mar", B201="Jun", B201="Sep")), E201*0.9, E201) -> 22244.2 | L201: =$K201*$J201 -> 4181909.6 | M201: =(K201-H201)*J201 -> 1672763.8

Sheet Pivot Table 1
